Workbook

Sheet YÜKLEME
A1: PREFABRİK BİNA MALZEMELERİ | F1: YÜKLEME LİSTESİ
A3: 3+1 EL ÇİZİMİ / dış ölçü 1150 × 1050 cm / duvar yüksekliği 280 cm / dış 160 mm, iç 100 mm / verandasız, beşik çatı
A4: 06.10.2026 — İş Emri PM-DENEME-3ARTI1-1150x1050 r01. Tek bina. Kapılı ve pencereli panolar tek pano; doğramalar ayrıca sayılır. TASLAK: üretim ve sevkiyat listesi değildir.
A6: Sıra | B6: Kod | C6: Malzeme | D6: Ölçü (mm) | E6: Adet | F6: Birim | G6: Dayanak | H6: Açıklama
A7: Dış duvar panoları (160 mm)
A8: 1 | B8: D09 | C8: Dolu pano | D8: 1255 × 160 × 2800 | E8: =COUNTIF(Sayım!$A$5:$A$94,"D09") -> 23 | F8: adet | G8: Sayım
A9: 2 | B9: D10 | C9: 120×180 pencereli pano | D9: 1255 × 160 × 2800 | E9: =COUNTIF(Sayım!$A$5:$A$94,"D10") -> 3 | F9: adet | G9: Sayım | H9: Pencere ayrı kalem. Gerçek listelerde üst panel (h 800) + alt panel (h 200) diye yazılır.
A10: 3 | B10: D11 | C10: Dış kapılı pano | D10: 1255 × 160 × 2800 | E10: =COUNTIF(Sayım!$A$5:$A$94,"D11") -> 1 | F10: adet | G10: Sayım | H10: Kapı ayrı kalem; pano tek parça sayıldı.
A11: 4 | B11: D12 | C11: Özel dolu pano | D11: 1140 × 160 × 2800 | E11: =COUNTIF(Sayım!$A$5:$A$94,"D12") -> 2 | F11: adet | G11: Sayım | H11: Ölçüye kesim: cephenin son panosu.
A12: 5 | B12: D13 | C12: 120×120 pencereli pano | D12: 1255 × 160 × 2800 | E12: =COUNTIF(Sayım!$A$5:$A$94,"D13") -> 3 | F12: adet | G12: Sayım | H12: Pencere ayrı kalem. Gerçek listelerde üst panel (h 800) + alt panel (h 800) diye yazılır.
A13: 6 | B13: D14 | C13: Özel dolu pano | D13: 300 × 160 × 2800 | E13: =COUNTIF(Sayım!$A$5:$A$94,"D14") -> 2 | F13: adet | G13: Sayım | H13: Ölçüye kesim: cephenin son panosu. DAR PARÇA: böyle mi üretilecek, komşu panoyla mı paylaştırılacak (açık konu 1).
A14: 7 | B14: D15 | C14: 60×40 vasistaslı pano | D14: 1255 × 160 × 2800 | E14: =COUNTIF(Sayım!$A$5:$A$94,"D15") -> 2 | F14: adet | G14: Sayım | H14: Vasistas ayrı kalem. Gerçek listelerde oyma panel diye yazılır.
A15: İç duvar panoları (100 mm)
A16: 8 | B16: I12 | C16: Özel dolu pano | D16: 1205 × 100 × 2800 | E16: =COUNTIF(Sayım!$A$5:$A$94,"I12") -> 3 | F16: adet | G16: Sayım | H16: Birleşimde duvar yüzüne dayanan ya da ölçüye kesilen pano; boy çizimdeki net boydur.
A17: 9 | B17: I13 | C17: Özel dolu pano | D17: 512,5 × 100 × 2800 | E17: =COUNTIF(Sayım!$A$5:$A$94,"I13") -> 2 | F17: adet | G17: Sayım | H17: Birleşimde duvar yüzüne dayanan ya da ölçüye kesilen pano; boy çizimdeki net boydur.
A18: 10 | B18: I14 | C18: Dolu pano | D18: 1255 × 100 × 2800 | E18: =COUNTIF(Sayım!$A$5:$A$94,"I14") -> 11 | F18: adet | G18: Sayım
A19: 11 | B19: I15 | C19: İç kapılı pano | D19: 1255 × 100 × 2800 | E19: =COUNTIF(Sayım!$A$5:$A$94,"I15") -> 5 | F19: adet | G19: Sayım | H19: Kapı ayrı kalem; pano tek parça sayıldı.
A20: 12 | B20: I16 | C20: Özel dolu pano | D20: 577,5 × 100 × 2800 | E20: =COUNTIF(Sayım!$A$5:$A$94,"I16") -> 3 | F20: adet | G20: Sayım | H20: Birleşimde duvar yüzüne dayanan ya da ölçüye kesilen pano; boy çizimdeki net boydur.
A21: 13 | B21: I17 | C21: Özel dolu pano | D21: 627,5 × 100 × 2800 | E21: =COUNTIF(Sayım!$A$5:$A$94,"I17") -> 2 | F21: adet | G21: Sayım | H21: Birleşimde duvar yüzüne dayanan ya da ölçüye kesilen pano; boy çizimdeki net boydur.
A22: 14 | B22: I18 | C22: Özel dolu pano | D22: 1175 × 100 × 2800 | E22: =COUNTIF(Sayım!$A$5:$A$94,"I18") -> 2 | F22: adet | G22: Sayım | H22: Birleşimde duvar yüzüne dayanan ya da ölçüye kesilen pano; boy çizimdeki net boydur.
A23: 15 | B23: I19 | C23: Özel dolu pano | D23: 220 × 100 × 2800 | E23: =COUNTIF(Sayım!$A$5:$A$94,"I19") -> 2 | F23: adet | G23: Sayım | H23: Birleşimde duvar yüzüne dayanan ya da ölçüye kesilen pano; boy çizimdeki net boydur. DAR PARÇA: böyle mi üretilecek, komşu panoyla mı paylaştırılacak (açık konu 1).
A24: Kapı ve pencereler
A25: 16 | B25: P01 | C25: Pencere 120×120 | D25: 1200 × 1200 | E25: =COUNTIF(Sayım!$A$5:$A$94,"P01") -> 3 | F25: adet | G25: Sayım | H25: Ölçü en × yükseklik; eşik 800 mm.
A26: 17 | B26: P02 | C26: Pencere 120×180 | D26: 1200 × 1800 | E26: =COUNTIF(Sayım!$A$5:$A$94,"P02") -> 3 | F26: adet | G26: Sayım | H26: Ölçü en × yükseklik; eşik 200 mm.
A27: 18 | B27: P03 | C27: Vasistas 60×40 | D27: 600 × 400 | E27: =COUNTIF(Sayım!$A$5:$A$94,"P03") -> 2 | F27: adet | G27: Sayım | H27: Ölçü en × yükseklik; eşik 1600 mm.
A28: 19 | B28: K01 | C28: İç kapı | D28: Açıklık 820 | E28: =COUNTIF(Sayım!$A$5:$A$94,"K01") -> 5 | F28: adet | G28: Sayım | H28: 820 mm plandaki açıklıktır; ürün eni/boyu ve açılış yönü siparişte teyit edilmeli.
A29: 20 | B29: K03 | C29: Dış kapı 90 | D29: Açıklık 900 | E29: =COUNTIF(Sayım!$A$5:$A$94,"K03") -> 1 | F29: adet | G29: Sayım | H29: 900 mm plandaki açıklıktır; ürün ölçüsü siparişte teyit edilmeli.
A30: 21 | B30: — | C30: Pencere kör kasası 120/180 | D30: 1200 × 1800 | E30: =Metraj!B38 -> 3 | F30: adet | G30: Liste kuralı | H30: P6001 gerçek listesinde yalnız 120/180 pencerelerde. Teyit bekliyor.
A31: Bağlantı profilleri ve alt çerçeve
A32: 22 | B32: B02 | C32: 100×50 köşe bağlantısı | D32: 50 × 100 | E32: =COUNTIF(Sayım!$A$5:$A$94,"B02") -> 2 | F32: adet | G32: Çıkarım | H32: Adet plandan sayıldı. Kesit 160 / 100 mm duvar için çıkarım; profil ve kesim boyu mühendis teyidi bekliyor.
A33: 23 | B33: B05 | C33: Üçlü H bağlantı 100 | D33: 100 | E33: =COUNTIF(Sayım!$A$5:$A$94,"B05") -> 4 | F33: adet | G33: Çıkarım | H33: Adet plandan sayıldı. Kesit 160 / 100 mm duvar için çıkarım; profil ve kesim boyu mühendis teyidi bekliyor.
A34: 24 | B34: B06 | C34: 160×80 köşe bağlantısı | D34: 80 × 160 | E34: =COUNTIF(Sayım!$A$5:$A$94,"B06") -> 4 | F34: adet | G34: Çıkarım | H34: Adet plandan sayıldı. Kesit 160 / 100 mm duvar için çıkarım; profil ve kesim boyu mühendis teyidi bekliyor.
A35: 25 | B35: — | C35: 2'li H profil, dış pano eki (160'lık) | D35: L 2800 | E35: =Metraj!B34 -> 32 | F35: adet | G35: Liste kuralı | H35: Her cephede pano adedi − 1. P6001 gerçek listesinde tutuyor (19). Kulaklı / dübelli ayrımının kuralı yok.
A36: 26 | B36: — | C36: 2'li H profil, iç pano eki (100'lük) | D36: L 2800 | E36: =Metraj!B35 -> 19 | F36: adet | G36: Liste kuralı | H36: İç ekler − üçlü H'nin yerini aldığı ekler. P6001 gerçek listesinde tutuyor (5).
A37: 27 | B37: — | C37: Alt çerçeve, dış duvar (160'lık) | D37: L 3750 | E37: =Metraj!B36 -> 12 | F37: adet | G37: Liste kuralı | H37: Dış duvar boyu ÷ 3,75 m. P6001 gerçek listesinde tutuyor (9).
A38: 28 | B38: — | C38: Alt çerçeve, iç duvar (100'lük) | D38: L 3750 | E38: =Metraj!B37 -> 9 | F38: adet | G38: Liste kuralı | H38: İç duvar boyu ÷ 3,75 m. P6001 gerçek listesinde tutuyor (3).
A39: Çatı (beşik, %33; makaslar kısa kenarı geçer)
A40: 29 | B40: — | C40: Baş makas | D40: açıklık 10500 | E40: =Metraj!B40 -> 2 | F40: adet | G40: Liste kuralı | H40: Kalkan duvarların üstünde. Makas boyu ve kesiti mühendisten.
A41: 30 | B41: — | C41: Orta makas | D41: açıklık 10500 | E41: =Metraj!B41 -> 8 | F41: adet | G41: Liste kuralı | H41: Pano akslarında (kesilen panoda aralık kısalır). P6001 gerçek listesinde tutuyor (5).
A42: 31 | B42: — | C42: Çatı kaplaması, tek kat panel | D42: =CONCATENATE("L ",ROUNDUP(Metraj!B46*100,0)*10) -> L 5900 | E42: =Metraj!B45 -> 26 | F42: adet | G42: Kural | H42: Kapatma 100 cm (Lokman, 4 Ekim); boy eğimli boy + 5 cm taşma. Her yüzde mahya boyu ÷ kapatma genişliği.
...

Sheet Sayım
A1: MODELDEN ALINAN SAYIM — her satır bir eleman
A2: Kaynak: İş Emri PM-DENEME-3ARTI1-1150x1050 r01; Motor deneme kopyasının planı (DXF ve IFC ile aynı). Koordinatlar sol-ön dış köşeden, cm. Sıra kodu görünüş paftasındaki pano numarasıdır (cephede bakana göre soldan sağa).
A4: Kod | B4: Eleman | C4: Tür | D4: Duvar | E4: Sıra (pafta kodu) | F4: Boy / en (mm) | G4: Kalınlık (mm) | H4: Yükseklik (mm) | I4: Açıklık | J4: Merkez X (cm) | K4: Merkez Y (cm) | L4: IFC adı
A5: D09 | B5: Dolu pano | C5: Dış pano | D5: Ön cephe | E5: Ö1 | F5: 1255 | G5: 160 | H5: 2800 | J5: 78.75 | K5: 8 | L5: PANO_D_TAM_125.5_00
A6: D10 | B6: 120×180 pencereli pano | C6: Dış pano | D6: Ön cephe | E6: Ö2 | F6: 1255 | G6: 160 | H6: 2800 | I6: pencere 120×180 | J6: 204.25 | K6: 8 | L6: PANO_D_TAM_125.5_01
A7: P02 | B7: Pencere 120×180 | C7: Pencere | D7: Ön cephe | E7: Ö2 | F7: 1200 | H7: 1800 | I7: pencere 120×180 | J7: 204.25 | K7: 8
A8: D10 | B8: 120×180 pencereli pano | C8: Dış pano | D8: Ön cephe | E8: Ö3 | F8: 1255 | G8: 160 | H8: 2800 | I8: pencere 120×180 | J8: 329.75 | K8: 8 | L8: PANO_D_TAM_125.5_02
A9: P02 | B9: Pencere 120×180 | C9: Pencere | D9: Ön cephe | E9: Ö3 | F9: 1200 | H9: 1800 | I9: pencere 120×180 | J9: 329.75 | K9: 8
A10: D11 | B10: Dış kapılı pano | C10: Dış pano | D10: Ön cephe | E10: Ö4 | F10: 1255 | G10: 160 | H10: 2800 | I10: dış kapı 90 | J10: 455.25 | K10: 8 | L10: PANO_D_TAM_125.5_03
A11: K03 | B11: Dış kapı 90 | C11: Kapı | D11: Ön cephe | E11: Ö4 | F11: 900 | I11: dış kapı 90 | J11: 455.25 | K11: 8
A12: D09 | B12: Dolu pano | C12: Dış pano | D12: Ön cephe | E12: Ö5 | F12: 1255 | G12: 160 | H12: 2800 | J12: 580.75 | K12: 8 | L12: PANO_D_TAM_125.5_04
A13: D09 | B13: Dolu pano | C13: Dış pano | D13: Ön cephe | E13: Ö6 | F13: 1255 | G13: 160 | H13: 2800 | J13: 706.25 | K13: 8 | L13: PANO_D_TAM_125.5_05
A14: D10 | B14: 120×180 pencereli pano | C14: Dış pano | D14: Ön cephe | E14: Ö7 | F14: 1255 | G14: 160 | H14: 2800 | I14: pencere 120×180 | J14: 831.75 | K14: 8 | L14: PANO_D_TAM_125.5_06
A15: P02 | B15: Pencere 120×180 | C15: Pencere | D15: Ön cephe | E15: Ö7 | F15: 1200 | H15: 1800 | I15: pencere 120×180 | J15: 831.75 | K15: 8
A16: D09 | B16: Dolu pano | C16: Dış pano | D16: Ön cephe | E16: Ö8 | F16: 1255 | G16: 160 | H16: 2800 | J16: 957.25 | K16: 8 | L16: PANO_D_TAM_125.5_07
A17: D12 | B17: Özel dolu pano | C17: Dış pano | D17: Ön cephe | E17: Ö9 | F17: 1140 | G17: 160 | H17: 2800 | J17: 1077 | K17: 8 | L17: PANO_D_OZEL_114.0_08
A18: I12 | B18: Özel dolu pano | C18: İç pano | D18: İç duvar 1 (y = 321.75 cm, soldan sağa) | E18: İ1-1 | F18: 1205 | G18: 100 | H18: 2800 | J18: 1022.5 | K18: 321.75 | L18: PANO_I_OZEL_120.5_09
A19: I13 | B19: Özel dolu pano | C19: İç pano | D19: İç duvar 1 (y = 321.75 cm, soldan sağa) | E19: İ1-2 | F19: 512.5 | G19: 100 | H19: 2800 | J19: 1108.38 | K19: 321.75 | L19: PANO_I_OZEL_51.2_10
A20: I14 | B20: Dolu pano | C20: İç pano | D20: İç duvar 2 (y = 447.25 cm, soldan sağa) | E20: İ2-1 | F20: 1255 | G20: 100 | H20: 2800 | J20: 580.75 | K20: 447.25 | L20: PANO_I_TAM_125.5_11
A21: I15 | B21: İç kapılı pano | C21: İç pano | D21: İç duvar 2 (y = 447.25 cm, soldan sağa) | E21: İ2-2 | F21: 1255 | G21: 100 | H21: 2800 | I21: iç kapı 82 | J21: 706.25 | K21: 447.25 | L21: PANO_I_TAM_125.5_12
A22: K01 | B22: İç kapı | C22: Kapı | D22: İç duvar 2 (y = 447.25 cm, soldan sağa) | E22: İ2-2 | F22: 820 | I22: iç kapı 82 | J22: 706.25 | K22: 447.25
A23: I14 | B23: Dolu pano | C23: İç pano | D23: İç duvar 2 (y = 447.25 cm, soldan sağa) | E23: İ2-3 | F23: 1255 | G23: 100 | H23: 2800 | J23: 831.75 | K23: 447.25 | L23: PANO_I_TAM_125.5_13
A24: I16 | B24: Özel dolu pano | C24: İç pano | D24: İç duvar 2 (y = 447.25 cm, soldan sağa) | E24: İ2-4 | F24: 577.5 | G24: 100 | H24: 2800 | J24: 923.38 | K24: 447.25 | L24: PANO_I_OZEL_57.8_14
A25: I14 | B25: Dolu pano | C25: İç pano | D25: İç duvar 3 (y = 635.5 cm, soldan sağa) | E25: İ3-1 | F25: 1255 | G25: 100 | H25: 2800 | J25: 580.75 | K25: 635.5 | L25: PANO_I_TAM_125.5_15
A26: I15 | B26: İç kapılı pano | C26: İç pano | D26: İç duvar 3 (y = 635.5 cm, soldan sağa) | E26: İ3-2 | F26: 1255 | G26: 100 | H26: 2800 | I26: iç kapı 82 | J26: 706.25 | K26: 635.5 | L26: PANO_I_TAM_125.5_16
A27: K01 | B27: İç kapı | C27: Kapı | D27: İç duvar 3 (y = 635.5 cm, soldan sağa) | E27: İ3-2 | F27: 820 | I27: iç kapı 82 | J27: 706.25 | K27: 635.5
A28: I17 | B28: Özel dolu pano | C28: İç pano | D28: İç duvar 3 (y = 635.5 cm, soldan sağa) | E28: İ3-3 | F28: 627.5 | G28: 100 | H28: 2800 | J28: 800.38 | K28: 635.5 | L28: PANO_I_YARIM_62.8_17
A29: I15 | B29: İç kapılı pano | C29: İç pano | D29: İç duvar 3 (y = 635.5 cm, soldan sağa) | E29: İ3-4 | F29: 1255 | G29: 100 | H29: 2800 | I29: iç kapı 82 | J29: 894.5 | K29: 635.5 | L29: PANO_I_TAM_125.5_18
A30: K01 | B30: İç kapı | C30: Kapı | D30: İç duvar 3 (y = 635.5 cm, soldan sağa) | E30: İ3-4 | F30: 820 | I30: iç kapı 82 | J30: 894.5 | K30: 635.5
A31: I14 | B31: Dolu pano | C31: İç pano | D31: İç duvar 3 (y = 635.5 cm, soldan sağa) | E31: İ3-5 | F31: 1255 | G31: 100 | H31: 2800 | J31: 1020 | K31: 635.5 | L31: PANO_I_TAM_125.5_19
A32: I13 | B32: Özel dolu pano | C32: İç pano | D32: İç duvar 3 (y = 635.5 cm, soldan sağa) | E32: İ3-6 | F32: 512.5 | G32: 100 | H32: 2800 | J32: 1108.38 | K32: 635.5 | L32: PANO_I_OZEL_51.2_20
A33: D09 | B33: Dolu pano | C33: Dış pano | D33: Arka cephe | E33: A9 | F33: 1255 | G33: 160 | H33: 2800 | J33: 78.75 | K33: 1042 | L33: PANO_D_TAM_125.5_21
A34: D13 | B34: 120×120 pencereli pano | C34: Dış pano | D34: Arka cephe | E34: A8 | F34: 1255 | G34: 160 | H34: 2800 | I34: pencere 120×120 | J34: 204.25 | K34: 1042 | L34: PANO_D_TAM_125.5_22
A35: P01 | B35: Pencere 120×120 | C35: Pencere | D35: Arka cephe | E35: A8 | F35: 1200 | H35: 1200 | I35: pencere 120×120 | J35: 204.25 | K35: 1042
A36: D09 | B36: Dolu pano | C36: Dış pano | D36: Arka cephe | E36: A7 | F36: 1255 | G36: 160 | H36: 2800 | J36: 329.75 | K36: 1042 | L36: PANO_D_TAM_125.5_23
A37: D09 | B37: Dolu pano | C37: Dış pano | D37: Arka cephe | E37: A6 | F37: 1255 | G37: 160 | H37: 2800 | J37: 455.25 | K37: 1042 | L37: PANO_D_TAM_125.5_24
A38: D09 | B38: Dolu pano | C38: Dış pano | D38: Arka cephe | E38: A5 | F38: 1255 | G38: 160 | H38: 2800 | J38: 580.75 | K38: 1042 | L38: PANO_D_TAM_125.5_25
A39: D13 | B39: 120×120 pencereli pano | C39: Dış pano | D39: Arka cephe | E39: A4 | F39: 1255 | G39: 160 | H39: 2800 | I39: pencere 120×120 | J39: 706.25 | K39: 1042 | L39: PANO_D_TAM_125.5_26
A40: P01 | B40: Pencere 120×120 | C40: Pencere | D40: Arka cephe | E40: A4 | F40: 1200 | H40: 1200 | I40: pencere 120×120 | J40: 706.25 | K40: 1042
A41: D09 | B41: Dolu pano | C41: Dış pano | D41: Arka cephe | E41: A3 | F41: 1255 | G41: 160 | H41: 2800 | J41: 831.75 | K41: 1042 | L41: PANO_D_TAM_125.5_27
...

Sheet Metraj
A1: TÜRETİLEN KALEMLER — kural, girdi ve formül
A2: Mavi: girdi (modelden ya da kuraldan). Siyah: formül. P6001 sütunu aynı formülü P6001'in girdileriyle hesaplar; yanındaki sütun P6001'in gerçek yükleme listesindeki adettir (60 m², İkranur Prefabrik; 21 Eylül 2026 analizi). Tutmayan kural kırmızı ✗ ile durur.
A4: Kalem | B4: Bu yapı | C4: P6001 (aynı formül) | D4: P6001 gerçek liste | E4: Tutuyor mu | F4: Kural ve kaynağı
A5: Girdiler · yapı
A6: Dış ölçü, genişlik (cm) | B6: 1150 | C6: 773 | F6: İş Emri: dış ölçü (Lokman, 6 Ekim 18:50). P6001: 6 pano × 125,5 + 20.
A7: Dış ölçü, derinlik (cm) | B7: 1050 | C7: 763 | F7: İş Emri: dış ölçü. P6001: 6 pano × 125,5 + 10.
A8: Makas açıklığı (cm) | B8: 1050 | C8: 773 | F8: Makaslar kısa kenarı geçer (Lokman, 20–21 Eylül). Bu yapıda derinlik; P6001'de genişlik.
A9: Mahya boyunca bina boyu (cm) | B9: 1150 | C9: 763 | F9: Makas açıklığına dik kenar.
A10: Saçak (cm) | B10: 30 | C10: 30 | F10: P6001 çizim kuralı: saçak 30 cm.
A11: Çatı eğimi | B11: 0.33 | C11: 0.33 | F11: P6001 çizim kuralı: %33.
A12: Girdiler · modelden sayılanlar
A13: Dış pano adedi | B13: =COUNTIF(Sayım!$C$5:$C$94,"Dış pano") -> 36 | C13: 25 | F13: Sayım sayfasından.
A14: Dış duvar koşusu (kesintisiz duvar) | B14: 4 | C14: 6 | F14: Plandan: dört cephe. P6001'de veranda girintisiyle 6.
A15: İç pano adedi | B15: =COUNTIF(Sayım!$C$5:$C$94,"İç pano") -> 30 | C15: 11 | F15: Sayım sayfasından.
A16: İç duvar koşusu | B16: 7 | C16: 4 | F16: Plandan.
A17: Üçlü H (iç–iç T birleşimi) | B17: =COUNTIFS(Sayım!$C$5:$C$94,"Bağlantı",Sayım!$D$5:$D$94,"İç duvar T birleşimi") -> 4 | C17: 2 | F17: Sayım sayfasından.
A18: Dış pano boyları toplamı (m) | B18: =SUMIFS(Sayım!$F$5:$F$94,Sayım!$C$5:$C$94,"Dış pano")/1000 -> 43.04 | C18: 30.02 | F18: Sayım sayfasından.
A19: İç pano boyları toplamı (m) | B19: =SUMIFS(Sayım!$F$5:$F$94,Sayım!$C$5:$C$94,"İç pano")/1000 -> 30.4975 | C19: 11.155 | F19: Sayım sayfasından.
A20: Mahya boyunca pano aksı sayısı | B20: 10 | C20: 7 | F20: Mahyaya paralel dış duvarın pano adedi + 1.
A21: 120×180 pencere adedi | B21: =COUNTIF(Sayım!$A$5:$A$94,"P02") -> 3 | C21: 2 | F21: Sayım sayfasından.
A22: Girdiler · kural katsayıları
A23: Alt çerçeve parça boyu (m) | B23: 3.75 | C23: 3.75 | F23: P6001 gerçek listesi: 100'lük ve 60'lık alt çerçeve L 3750.
A24: Çatı kaplamasının kapatma genişliği (m) | B24: 1 | C24: 0.87 | F24: Lokman, 4 Ekim 15:18: tek kat panel 100 cm kapatır. 2021 ürününde 87 cm.
A25: Kaplamanın saçaktan taşması (m) | B25: 0.05 | C25: 0.05 | F25: Mühendis, 4 Ekim 12:14: kaplama saçaktan 5 cm taşar.
A26: Sac parçasının bindirmeden sonraki boyu (m) | B26: 2.5 | C26: 2.5 | F26: Lokman, 3 Ekim 13:27: saçak, mahya ve alın sacında bindirme 30 cm; L 2800 parçada uzunluk ÷ 2,5.
A27: Aşık aralığı (m) | B27: 0.6 | C27: 0.6 | F27: Montaj paftası notu: aşıklar 60 cm aralıklı.
A28: Aşık parça boyu (m) | B28: 3.75 | C28: 3.75 | F28: P6001 gerçek listesi: omega aşık L 3750. (Çelik listelerinde L 4200.)
A29: Aşık zayiatı | B29: 0.05 | C29: 0.05 | F29: Gerçek listelere uydurulan pay; teyit bekliyor.
A30: Alçıpan levhası (m²) | B30: 3 | C30: 3 | F30: 1,2 × 2,5 m.
A31: Şilte (m²/adet) | B31: 9.6 | C31: 9.6 | F31: Çelik listeleri: çatı şiltesi 9,6 m²/adet.
A32: Dere parçasının bindirmeden sonraki boyu (m) | B32: 3.8 | C32: 3.8 | F32: Excel hesaplama motoru (CTKBF): L 4000 − 20 cm bindirme.
A33: Bağlantı profilleri
A34: 2'li H, dış pano ekleri | B34: =B13-B14 -> 32 | C34: =C13-C14 -> 19 | D34: 19 | E34: =IF(C34=D34,"✓","✗") -> ✓ | F34: Her koşuda pano adedi − 1 ek. P6001 gerçek listesi: H 100 = 19.
A35: 2'li H, iç pano ekleri | B35: =B15-B16-B17 -> 19 | C35: =C15-C16-C17 -> 5 | D35: 5 | E35: =IF(C35=D35,"✓","✗") -> ✓ | F35: İç ekler − üçlü H'nin yerini aldığı ekler. P6001 gerçek listesi: H 60 = 5.
A36: Alt çerçeve, dış duvar (adet) | B36: =ROUNDUP(B18/B23,0) -> 12 | C36: =ROUNDUP(C18/C23,0) -> 9 | D36: 9 | E36: =IF(C36=D36,"✓","✗") -> ✓ | F36: Dış pano boyları toplamı ÷ parça boyu, yukarı yuvarlanır. Kapı boşluğu düşülmez (P6001 listesine göre).
A37: Alt çerçeve, iç duvar (adet) | B37: =ROUNDUP(B19/B23,0) -> 9 | C37: =ROUNDUP(C19/C23,0) -> 3 | D37: 3 | E37: =IF(C37=D37,"✓","✗") -> ✓ | F37: İç pano boyları toplamı ÷ parça boyu.
A38: Pencere kör kasası 120/180 | B38: =B21 -> 3 | C38: =C21 -> 2 | D38: 2 | E38: =IF(C38=D38,"✓","✗") -> ✓ | F38: P6001 gerçek listesi: yalnız 120/180 pencerelerde kör kasa (2 pencere, 2 kasa). Teyit bekliyor.
A39: Çatı (beşik)
A40: Baş makas | B40: =2 -> 2 | C40: =2 -> 2 | D40: 2 | E40: =IF(C40=D40,"✓","✗") -> ✓ | F40: İki kalkan duvarın üstünde.
A41: Orta makas | B41: =B20-2 -> 8 | C41: =C20-2 -> 5 | D41: 5 | E41: =IF(C41=D41,"✓","✗") -> ✓ | F41: Makaslar pano akslarında. P6001 gerçek listesi: 6 pano boyunca 2 baş + 5 orta.
...

Sheet Açık konular
A1: AÇIK KONULAR — listeye girmeyenler ve teyit bekleyenler
A3: No | B3: Konu | C3: Bu yapıda durum | D3: P6001 gerçek listesinde (60 m²) | E3: Gereken
A4: 1 | B4: Dar kalan son parça | C4: Arkada 30 cm dış pano (2 adet), arka yatak odalarının duvarlarında 22 cm iç pano (2 adet). | D4: Yok (tam modül). | E4: Böyle mi üretilecek, bir önceki panoyla mı paylaştırılacak? En az pano boyu.
A5: 2 | B5: 160 mm dış ve 100 mm iç duvarın bağlantı profilleri | C5: Köşe 160×80, iç köşe 100×50, üçlü H 100, 2'li H'lar: kesitler çıkarım. | D5: Köşe direği 100×100 ×6, 60×60 ×1; H 100 ×19; H 60 ×5; 3'lü H 60 ×2. | E5: Mühendisten profil listesi ve kesim boyları.
A6: 3 | B6: Dış–iç üçlü H (iç duvarın dış duvara dayandığı yer) | C6: 6 birleşim: 3'ü dış pano ekinde, 3'ü pano ortasında. Listeye yazılmadı. | D6: 3'lü H 100×100×60 ×2 (kulaklı 1 + dübelli 1). | E6: Pano ortasına gelen birleşim nasıl bağlanıyor?
A7: 4 | B7: Kulaklı / dübelli H ayrımı | C7: Ayrılmadı; 2'li H tek kalem. | D7: H 100: 8 kulaklı + 11 dübelli. | E7: Hangi eklerde kulaklı?
A8: 5 | B8: Çektirme U'su | C8: Listeye yazılmadı. | D8: 100'lük ×5, 60'lık ×3 (L 2440). | E8: Nerede sayılır?
A9: 6 | B9: Duvar omegası ve saçak omegası | C9: Listeye yazılmadı. | D9: 100'lük duvar omegası ×3, 60'lık ×15, saçak omegası ×7. | E9: Neyi taşıyor, nasıl sayılır?
A10: 7 | B10: Pencere U'su | C10: Listeye yazılmadı. | D10: ×6 (5 pencere). | E10: Pencere başına kural.
A11: 8 | B11: Tavan H'ı; alçıpanda beyaz–yeşil ayrımı | C11: Alçıpan toplam adet verildi; H ve ayrım yok. | D11: Tavan H'ı 1185 ×70; alçıpan 15 beyaz + 5 yeşil. | E11: H adedi kuralı; yeşil levha hangi mahallerde?
A12: 9 | B12: Makas boyu ve kesiti | C12: Adet verildi (2 baş + 8 orta); boy yazılmadı. | D12: Baş ve orta makas L 8230 (açıklık 7730). | E12: 10,50 m açıklık için makas ölçüsü ve statik.
A13: 10 | B13: Mahya bindirmesi | C13: 30 cm bindirmeyle 5 adet. | D13: 3 adet (bindirmesiz hesapla tutuyor). | E13: Prefabrikte mahya bindirmesi kaç cm?
A14: 11 | B14: Pencereli panonun yazılışı | C14: Tek pano + ayrı doğrama (Astra listesindeki gibi). | D14: Üst panel + alt panel + oyma panel ayrı kalemler. | E14: Üretim listesi hangi biçimi istiyor?
A15: 12 | B15: Vida, elektrik, sıhhi tesisat, boya | C15: Listeye yazılmadı. | D15: Dört ayrı grup. | E15: Çelik listelerindeki kurallar prefabrikte de geçerli mi?
A16: 13 | B16: Pencere ölçüleri | C16: El çizimindeki 240/240, 150/240, 100/240, 180/120, 60/60 standart ölçülere çevrildi. | D16: — | E16: Standart mı, özel doğrama mı?
